Watching for file changes with StatReloader
[13/May/2019 16:11:19] "GET /blog/archive/ HTTP/1.1" 200 504
./auto_run_server.sh: line 3: 23432 Killed                  python3 manage.py runserver localhost:8000
Watching for file changes with StatReloader
[13/May/2019 16:13:10] "GET /blog/archive/ HTTP/1.1" 200 504
Internal Server Error: /blog/2019/
Traceback (most recent call last):
  File "/home/django/.local/lib/python3.6/site-packages/django/core/handlers/exception.py", line 34, in inner
    response = get_response(request)
  File "/home/django/.local/lib/python3.6/site-packages/django/core/handlers/base.py", line 145, in _get_response
    response = self.process_exception_by_middleware(e, request)
  File "/home/django/.local/lib/python3.6/site-packages/django/core/handlers/base.py", line 143, in _get_response
    response = response.render()
  File "/home/django/.local/lib/python3.6/site-packages/django/template/response.py", line 106, in render
    self.content = self.rendered_content
  File "/home/django/.local/lib/python3.6/site-packages/django/template/response.py", line 83, in rendered_content
    content = template.render(context, self._request)
  File "/home/django/.local/lib/python3.6/site-packages/django/template/backends/django.py", line 61, in render
    return self.template.render(context)
  File "/home/django/.local/lib/python3.6/site-packages/django/template/base.py", line 171, in render
    return self._render(context)
  File "/home/django/.local/lib/python3.6/site-packages/django/template/base.py", line 163, in _render
    return self.nodelist.render(context)
  File "/home/django/.local/lib/python3.6/site-packages/django/template/base.py", line 937, in render
    bit = node.render_annotated(context)
  File "/home/django/.local/lib/python3.6/site-packages/django/template/base.py", line 904, in render_annotated
    return self.render(context)
  File "/home/django/.local/lib/python3.6/site-packages/django/template/defaulttags.py", line 209, in render
    nodelist.append(node.render_annotated(context))
  File "/home/django/.local/lib/python3.6/site-packages/django/template/base.py", line 904, in render_annotated
    return self.render(context)
  File "/home/django/.local/lib/python3.6/site-packages/django/template/defaulttags.py", line 443, in render
    url = reverse(view_name, args=args, kwargs=kwargs, current_app=current_app)
  File "/home/django/.local/lib/python3.6/site-packages/django/urls/base.py", line 90, in reverse
    return iri_to_uri(resolver._reverse_with_prefix(view, prefix, *args, **kwargs))
  File "/home/django/.local/lib/python3.6/site-packages/django/urls/resolvers.py", line 668, in _reverse_with_prefix
    raise NoReverseMatch(msg)
django.urls.exceptions.NoReverseMatch: Reverse for 'post_archive_month' with arguments '('2019', '5ì›”')' not found. 1 pattern(s) tried: ['blog/(?P<year>\\d{4})/(?P<month>[a-z]{3})/$']
[13/May/2019 16:13:18] "GET /blog/2019/ HTTP/1.1" 500 129417
/home/django/Frameworks/Django_Example/ch2/mysite/settings.py changed, reloading.
Watching for file changes with StatReloader
[13/May/2019 16:14:56] "GET /blog/2019/ HTTP/1.1" 200 491
[13/May/2019 16:15:01] "GET /blog/2019/may/ HTTP/1.1" 200 402
[13/May/2019 16:15:12] "GET /blog/post/third-post/ HTTP/1.1" 200 223
[13/May/2019 16:15:15] "GET /blog/2019/ HTTP/1.1" 200 491
[13/May/2019 16:15:17] "GET /blog/2019/may/ HTTP/1.1" 200 402
[13/May/2019 16:15:19] "GET /blog/post/third-post/ HTTP/1.1" 200 223
